Workbook

Sheet Vehicle Design
A1: LAUNCH VEHICLE DESIGN TOOL
A2: Yellow = Input | Blue = Calculated | Engine name must match Engine DB exactly | ΔV Allocation per stage must sum to Mission ΔV
A3: PARAMETER | B3: UNITS | D3: Stage 1 | G3: Stage 2 | J3: Stage 3
A5: MISSION REQUIREMENTS
A6: Vehicle Name | B6: New Glenn Block 2 (7x2)
A7: Target Orbit | B7: LEO 400km
A8: Payload Adapter Mass | B8: 200 | C8: ← Separation hardware mass between payload and vehicle
A9: Orbital Velocity (LEO) | B9: 7784 | C9: ← Target orbital velocity — 7784 m/s for 400km LEO; 7726 m/s for 200km
A10: Drag Loss | B10: 120 | C10: ← Aerodynamic drag loss — typically 100-150 m/s; relatively insensitive to thrust
A11: Gravity Loss Coefficient | B11: 1750 | C11: ← Gravity loss = coeff / TWR_liftoff; calibrated to ~1450 m/s at TWR=1.2; adjust to match known vehicles
A12: GTO Orbital ΔV | B12: 10400 | C12: ← Velocity needed at GTO perigee — ~10,200-10,500 m/s depending on inclination and target apogee
A13: Number of Stages | B13: 2 | C13: ← Active stages (enter 1-3)
A15: STAGE CONFIGURATION
A16: Stage Name | B16: text | E16: S1 First | H16: S2 Upper
A17: Engine (from Engine DB) | B17: name | E17: BE-4 Block 2 | H17: BE-3U Block 2
A18: Number of Engines | B18: count | E18: 7 | H18: 2
A19: Propellant Combination | B19: type | E19: LOX/CH4 | H19: LOX/LH2
A20: Propellant Mass (nominal) | B20: kg | E20: 770000 | H20: 75000
A21: Subcooling Gain (%) | B21: % | E21: 3.5 | H21: 0 | K21: 0
A22: Effective Propellant Mass | B22: kg | E22: =IFERROR(E20*(1+E21/100),"") | H22: =IFERROR(H20*(1+H21/100),"") | K22: =IFERROR(K20*(1+K21/100),"")
A23: LEO ΔV Fraction | B23: 0-1 | E23: 0.597 | H23: 0.403
A24: LEO ΔV Allocation | B24: m/s | E24: =IFERROR(E23*B37,"") | H24: =IFERROR(H23*B37,"") | K24: =IFERROR(K23*B37,"")
A25: Vac Isp Override | B25: s
A26: Vac Isp (from DB) | B26: s | E26: =IF(E25<>"",E25,IFERROR(VLOOKUP(E17,'Engine DB'!$A:$K,4,0),"Enter engine")) | H26: =IF(H25<>"",H25,IFERROR(VLOOKUP(H17,'Engine DB'!$A:$K,4,0),"Enter engine")) | K26: =IF(K25<>"",K25,IFERROR(VLOOKUP(K17,'Engine DB'!$A:$K,4,0),"Enter engine"))
A27: SL Isp (from DB) | B27: s | E27: =IFERROR(VLOOKUP(E17,'Engine DB'!$A:$K,5,0),"—") | H27: =IFERROR(VLOOKUP(H17,'Engine DB'!$A:$K,5,0),"—") | K27: =IFERROR(VLOOKUP(K17,'Engine DB'!$A:$K,5,0),"—")
A28: Atm Fraction (0-1) | B28: — | E28: 0.6 | H28: 1 | K28: 1
A29: Effective Isp (used) | B29: s | E29: =IFERROR(IF(ISNUMBER(E27),E27+E28*(E26-E27),E26),E26) | H29: =IFERROR(IF(ISNUMBER(H27),H27+H28*(H26-H27),H26),H26) | K29: =IFERROR(IF(ISNUMBER(K27),K27+K28*(K26-K27),K26),K26)
A30: GTO ΔV Fraction | B30: 0-1 | E30: 0.555 | H30: 0.445
A31: GTO ΔV Allocation | B31: m/s | E31: =IFERROR(E30*B38,"") | H31: =IFERROR(H30*B38,"") | K31: =IFERROR(K30*B38,"")
A33: MISSION ΔV ANALYSIS — Gravity loss computed from liftoff TWR
A34: Est. GLOW (stage masses only, no payload) | B34: =IFERROR(E20+E56,0)+IFERROR(H20+H56,0)+IFERROR(K20+K56,0)
A35: Stage 1 Liftoff TWR (est., no payload) | B35: =IFERROR(E18*IFERROR(VLOOKUP(E17,'Engine DB'!$A:$K,7,0),0)*1000/(B34*9.80665),"")
A36: Gravity Loss (= coeff / TWR) | B36: =IFERROR(B11/B35,"")
A37: LEO Mission ΔV (calculated) | B37: =IFERROR(B9+B10+B36,"")
A38: GTO Mission ΔV (calculated) | B38: =IFERROR(B12+B10+B36,"")
A39: LEO ΔV Allocation Check (should = LEO Mission ΔV above) | B39: =IFERROR(E24*1,0)+IFERROR(H24*1,0)+IFERROR(K24*1,0) | C39: =IF(ABS(B39-B37)<1,"✓ OK","⚠ Adjust stage allocations to sum to LEO Mission ΔV")
A40: Engine Mass per Engine | B40: kg | E40: =IFERROR(VLOOKUP(E17,'Engine DB'!$A:$K,8,0),"—") | H40: =IFERROR(VLOOKUP(H17,'Engine DB'!$A:$K,8,0),"—") | K40: =IFERROR(VLOOKUP(K17,'Engine DB'!$A:$K,8,0),"—")
A42: SUBSYSTEM MASS BREAKDOWN (auto-estimated; override any yellow cell)
A43: Tank Structure | B43: kg | E43: =IF(E20="","",E20/100*IF(E19="LOX/RP-1",3.5,IF(E19="LOX/LH2",6.5,IF(E19="LOX/CH4",3.8,IF(OR(E19="Solid HTPB",E19="Solid PBAN"),1.8,2.5))))) | H43: =IF(H20="","",H20/100*IF(H19="LOX/RP-1",3.5,IF(H19="LOX/LH2",6.5,IF(H19="LOX/CH4",3.8,IF(OR(H19="Solid HTPB",H19="Solid PBAN"),1.8,2.5))))) | K43: =IF(K20="","",K20/100*IF(K19="LOX/RP-1",3.5,IF(K19="LOX/LH2",6.5,IF(K19="LOX/CH4",3.8,IF(OR(K19="Solid HTPB",K19="Solid PBAN"),1.8,2.5)))))
A44: Pressurization System | B44: kg | E44: =IF(E20="","",E20/100*IF(E19="LOX/RP-1",0.4,IF(E19="LOX/LH2",0.6,IF(E19="LOX/CH4",0.4,IF(OR(E19="Solid HTPB",E19="Solid PBAN"),0.0,0.5))))) | H44: =IF(H20="","",H20/100*IF(H19="LOX/RP-1",0.4,IF(H19="LOX/LH2",0.6,IF(H19="LOX/CH4",0.4,IF(OR(H19="Solid HTPB",H19="Solid PBAN"),0.0,0.5))))) | K44: =IF(K20="","",K20/100*IF(K19="LOX/RP-1",0.4,IF(K19="LOX/LH2",0.6,IF(K19="LOX/CH4",0.4,IF(OR(K19="Solid HTPB",K19="Solid PBAN"),0.0,0.5)))))
...

Sheet README
A1: LAUNCH VEHICLE DESIGN TOOL — User Guide
A3: HOW TO USE
A4: 1. Go to 'Vehicle Design' tab — this is your main working sheet.
A5: 2. Fill in Mission Requirements (yellow cells): payload mass, target orbit, delta-v budget.
A6: 3. For each stage, enter the number of stages (1-3) and configure each stage:
A7: • Engine: Type the exact engine name from the 'Engine DB' tab. Isp will auto-populate via VLOOKUP.
A8: • Number of Engines: How many of that engine on this stage.
A9: • Propellant Combination: Must match exactly (e.g. LOX/RP-1, LOX/LH2, LOX/CH4, Solid HTPB, NTO/MMH).
A10: • Propellant Mass: Total usable propellant mass for this stage in kg.
A11: • Vac Isp Override: Leave blank to use the Engine DB value. Enter a number to override.
A13: 4. Subsystem masses auto-calculate from parametric models in the 'Propellants' tab.
A14: • Yellow cells in the subsystem section can be manually overridden with known values.
... A44: Treat parallel-burn vehicles (Soyuz, Ariane 5) as series stages for delta-v calculation.

Sheet Engine DB
A1: ROCKET ENGINE DATABASE — Real-World Performance Data
A2: Engine Name | B2: Vehicle Application | C2: Propellant | D2: Vac Isp (s) | E2: SL Isp (s) | F2: Vac Thrust (kN) | G2: SL Thrust (kN) | H2: Engine Mass (kg) | I2: Chamber Press (bar) | J2: Expansion Ratio | K2: Notes
A3: ── LOX/RP-1 ──
A4: Merlin 1D | B4: Falcon 9 S1 | C4: LOX/RP-1 | D4: 311 | E4: 282 | F4: 934 | G4: 845 | H4: 470 | I4: 97 | J4: 16 | K4: 9 engines on F9 first stage; sea-level optimized
A5: Merlin 1D Vac | B5: Falcon 9 S2 | C5: LOX/RP-1 | D5: 348 | E5: — | F5: 934 | G5: — | H5: 490 | I5: 97 | J5: 165 | K5: Vacuum-optimized fixed nozzle extension
A6: RD-180 | B6: Atlas V CBC | C6: LOX/RP-1 | D6: 338 | E6: 311 | F6: 4152 | G6: 3828 | H6: 5480 | I6: 257 | J6: 36.4 | K6: Dual-chamber single-turbopump; Russian-designed
A7: RD-107A | B7: Soyuz Strap-on | C7: LOX/RP-1 | D7: 320 | E7: 263 | F7: 1020 | G7: 838 | H7: 1190 | I7: 60 | J7: 21 | K7: 4 strap-on boosters; 4 fixed + 4 vernier chambers
A8: RD-108A | B8: Soyuz Core | C8: LOX/RP-1 | D8: 320 | E8: 257 | F8: 990 | G8: 792 | H8: 1278 | I8: 60 | J8: 21 | K8: Core stage; 4 main + 4 vernier chambers
A9: RD-0124 | B9: Soyuz S3 / Angara S2 | C9: LOX/RP-1 | D9: 359 | E9: 311 | F9: 294 | G9: — | H9: 480 | I9: 157 | J9: 30 | K9: High-performance staged combustion upper stage
A10: F-1 | B10: Saturn V S-IC | C10: LOX/RP-1 | D10: 304 | E10: 263 | F10: 7740 | G10: 6770 | H10: 8391 | I10: 70 | J10: 16 | K10: 5 engines on Saturn V first stage; largest US engine
A11: RD-191 | B11: Angara S1 | C11: LOX/RP-1 | D11: 337 | E11: 311 | F11: 2090 | G11: 1922 | H11: 2200 | I11: 263 | J11: 37 | K11: Single-chamber RD-180 derivative
A12: NK-33 (AJ-26) | B12: Antares S1 | C12: LOX/RP-1 | D12: 331 | E12: 297 | F12: 1638 | G12: 1510 | H12: 1222 | I12: 146 | J12: 27 | K12: Soviet N1 engine; modernized as AJ-26
A13: Rutherford | B13: Electron S1 | C13: LOX/RP-1 | D13: 311 | E13: 303 | F13: 24 | G13: 22 | H13: 35 | I13: 145 | J13: 11 | K13: 9 engines; electric-pump cycle; additive manufactured
A14: Rutherford Vac | B14: Electron S2 | C14: LOX/RP-1 | D14: 343 | E14: — | F14: 25 | G14: — | H14: 35 | I14: 145 | J14: 250 | K14: Vacuum variant; electric-pump cycle
A15: ── LOX/LH2 ──
A16: RS-25 (SSME) | B16: SLS Core / Shuttle | C16: LOX/LH2 | D16: 452 | E16: 366 | F16: 2090 | G16: 1860 | H16: 3177 | I16: 206 | J16: 69 | K16: 3x on SLS; 4x on Shuttle; high-performance SSME
A17: RL-10A-4-2 | B17: Atlas V Centaur | C17: LOX/LH2 | D17: 451 | E17: — | F17: 99 | G17: — | H17: 168 | I17: 28 | J17: 84 | K17: Expander cycle; multiple restarts
A18: RL-10B-2 | B18: Delta IV DCSS | C18: LOX/LH2 | D18: 462 | E18: — | F18: 110 | G18: — | H18: 277 | I18: 44 | J18: 285 | K18: Extendable carbon-carbon nozzle
A19: RL-10C-1 | B19: Vulcan Centaur | C19: LOX/LH2 | D19: 450 | E19: — | F19: 102 | G19: — | H19: 190 | I19: 34 | J19: 84 | K19: Updated RL-10; simplified nozzle
A20: RL-10C-3 | B20: SLS ICPS | C20: LOX/LH2 | D20: 460 | E20: — | F20: 110 | G20: — | H20: 190 | I20: 34 | J20: 150 | K20: High-expansion ratio variant
A21: Vulcain 2 | B21: Ariane 5 EPC | C21: LOX/LH2 | D21: 431 | E21: 318 | F21: 1340 | G21: 960 | H21: 1686 | I21: 115 | J21: 60 | K21: Gas-generator cycle; Ariane 5 core
A22: Vinci | B22: Ariane 6 ULPM | C22: LOX/LH2 | D22: 465 | E22: — | F22: 180 | G22: — | H22: 550 | I22: 61 | J22: 240 | K22: Expander cycle; restartable upper stage
A23: HM7B | B23: Ariane 5 ESC-A | C23: LOX/LH2 | D23: 446 | E23: — | F23: 65 | G23: — | H23: 165 | I23: 35 | J23: 83 | K23: Gas-generator; multiple restarts
A24: J-2 | B24: Saturn V S-II / S-IVB | C24: LOX/LH2 | D24: 421 | E24: — | F24: 1033 | G24: — | H24: 1788 | I24: 52 | J24: 27.5 | K24: 5x on S-II; 1x on S-IVB; restartable
A25: RS-68A | B25: Delta IV Heavy CBC | C25: LOX/LH2 | D25: 412 | E25: 365 | F25: 3370 | G25: 2949 | H25: 6597 | I25: 97 | J25: 21.5 | K25: Gas-generator; simple design; largest H2 engine
A26: BE-3U | B26: New Glenn S2 | C26: LOX/LH2 | D26: 440 | E26: — | F26: 710 | G26: — | H26: 2700 | I26: 90 | J26: 200 | K26: Blue Origin upper stage engine; expander cycle; 2x on NG 7x2
A27: BE-3U Block 2 | B27: New Glenn Block 2 S2 | C27: LOX/LH2 | D27: 440 | E27: — | F27: 890 | G27: — | H27: 2700 | I27: 90 | J27: 200 | K27: Upgraded BE-3U; 890 kN vac (200,000 lbf) vs 710 kN original; 4x on NG 9x4; Isp unchanged
A28: ── LOX/CH4 ──
A29: Raptor 2 | B29: Starship / Super Heavy | C29: LOX/CH4 | D29: 350 | E29: 327 | F29: 2350 | G29: 2200 | H29: 1500 | I29: 330 | J29: 32 | K29: Full-flow staged combustion; 33x on Super Heavy
A30: Raptor Vac | B30: Starship upper | C30: LOX/CH4 | D30: 380 | E30: — | F30: 2200 | G30: — | H30: 1600 | I30: 330 | J30: 107 | K30: Vacuum variant; large fixed nozzle; 3x on Starship
A31: BE-4 | B31: Vulcan / New Glenn S1 | C31: LOX/CH4 | D31: 339 | E31: 310 | F31: 2400 | G31: 2100 | H31: 4760 | I31: 134 | J31: 40 | K31: Oxygen-rich staged combustion; 2x Vulcan / 7x NG 7x2 baseline
A32: BE-4 Block 2 | B32: New Glenn Block 2 S1 | C32: LOX/CH4 | D32: 339 | E32: 310 | F32: 2847 | G32: 2490 | H32: 4760 | I32: 134 | J32: 40 | K32: Upgraded BE-4; 2,847 kN SL (640,000 lbf) with propellant subcooling; vac est. proportional; same Isp
A33: ── NTO/MMH ──
A34: AJ-10-190 | B34: Orion SPS / STS OMS | C34: NTO/MMH | D34: 316 | E34: — | F34: 27 | G34: — | H34: 118 | I34: 9 | J34: 49 | K34: Pressure-fed; restartable; long heritage
A35: Aestus | B35: Ariane 5 ATV | C35: NTO/MMH | D35: 324 | E35: — | F35: 29 | G35: — | H35: 111 | I35: 11 | J35: 84 | K35: Pressure-fed; restartable; ESA upper stage
A36: ── NTO/UDMH ──
A37: Vikas | B37: PSLV / GSLV S2 | C37: NTO/UDMH | D37: 293 | E37: 270 | F37: 800 | G37: 725 | H37: 634 | I37: 58 | J37: 16 | K37: Indian engine; Ariane Viking derivative
A38: YF-20 (cluster) | B38: Long March S1 | C38: NTO/UDMH | D38: 289 | E38: 259 | F38: 2962 | G38: 2799 | H38: 4000 | I38: 65 | J38: 14 | K38: 4-chamber cluster used on CZ-2/3/4 first stages
A39: ── Solid HTPB ──
A40: SRB (SLS 5-seg) | B40: SLS Block 1 | C40: Solid HTPB | D40: 269 | E40: 242 | F40: 16000 | G40: 14900 | H40: 90718 | I40: 62 | J40: 7.5 | K40: Largest SRB ever flown; 2x on SLS
...

Sheet Vehicle DB
A1: REFERENCE LAUNCH VEHICLE DATABASE — Real Vehicle Mass & Performance Data
A2: Vehicle | B2: Country | C2: Operator | D2: First Flight | E2: Status | F2: Payload LEO (kg) | G2: Payload GTO (kg) | H2: Payload TLI (kg) | I2: GLOW (kg) | J2: Height (m) | K2: Diameter (m) | L2: Notes
A3: Falcon 9 Block 5 | B3: USA | C3: SpaceX | D3: 2018 | E3: Active | F3: 22800 | G3: 8300 | H3: — | I3: 549054 | J3: 70 | K3: 3.66 | L3: 22,800 kg LEO expendable / 17,400 kg reusable; partially reusable first stage
A4: Falcon Heavy | B4: USA | C4: SpaceX | D4: 2018 | E4: Active | F4: 63800 | G4: 26700 | H4: — | I4: 1420788 | J4: 70 | K4: 12.2 | L4: Expendable config; 3 F9 cores; center core reinforced
A5: Atlas V 401 | B5: USA | C5: ULA | D5: 2002 | E5: Active (limited) | F5: 9750 | G5: 4750 | H5: — | I5: 334500 | J5: 58.3 | K5: 3.81 | L5: 401 = 4m fairing, 0 SRBs, 1 RL-10; 551 config adds 5 GEM SRBs and dual RL-10
A6: Delta IV Heavy | B6: USA | C6: ULA | D6: 2004 | E6: Retired 2024 | F6: 28370 | G6: 14220 | H6: — | I6: 733400 | J6: 72 | K6: 15 | L6: 3 identical CBCs; heaviest US expendable before SLS
A7: Ariane 5 ECA | B7: Europe | C7: Arianespace | D7: 2002 | E7: Retired 2023 | F7: 21000 | G7: 10865 | H7: — | I7: 777000 | J7: 59 | K7: 5.4 | L7: 2 EAP solid strap-ons + EPC LOX/LH2 core + ESC-A LOX/LH2 upper
A8: Soyuz-2.1b | B8: Russia | C8: Roscosmos | D8: 2006 | E8: Active | F8: 8200 | G8: 2800 | H8: — | I8: 312000 | J8: 46.3 | K8: 10.3 | L8: Classic 3-stage parallel burn; boosters + core ignite at liftoff
A9: Saturn V | B9: USA | C9: NASA | D9: 1967 | E9: Retired 1973 | F9: 130000 | G9: — | H9: 48600 | I9: 2970000 | J9: 110.6 | K9: 10.1 | L9: Apollo program; still the most powerful rocket ever flown
A10: SLS Block 1 | B10: USA | C10: NASA | D10: 2022 | E10: Active | F10: 95000 | G10: — | H10: 27000 | I10: 2608000 | J10: 98 | K10: 8.4 | L10: Artemis program; RS-25 core + 2 SLS SRBs + ICPS upper stage
A11: New Glenn (7x2 Baseline) | B11: USA | C11: Blue Origin | D11: 2025 | E11: Active | F11: 45000 | G11: 13000 | H11: — | I11: 1000000 | J11: 98 | K11: 7 | L11: First flight Jan 2025; 7 BE-4 + 2 BE-3U; 7m fairing; Blue Origin claimed 45t LEO / 13t GTO
A12: New Glenn Block 2 (7x2 Upgraded) | B12: USA | C12: Blue Origin | D12: 2026 | E12: Development | F12: — | G12: — | H12: — | I12: 1000000 | J12: 98 | K12: 7 | L12: Upgraded BE-4 Block 2 (2,847 kN SL w/ subcooling) + BE-3U Block 2 (890 kN); no updated payload figures released by Blue Origin
A13: New Glenn 9x4 | B13: USA | C13: Blue Origin | D13: 2027 | E13: Development | F13: 70000 | G13: 14000 | H13: 20000 | I13: 1300000 | J13: 105 | K13: 8.7 | L13: Heavy-lift variant; 9 BE-4 Block 2 S1 + 4 BE-3U Block 2 S2; 8.7m fairing; >70t LEO / >14t GTO announced; prop masses estimated
A14: Starship (IFT-6 config) | B14: USA | C14: SpaceX | D14: 2023 | E14: Development | F14: 150000 | G14: — | H14: — | I14: 5000000 | J14: 121 | K14: 9 | L14: Fully reusable target; 150t LEO is aspirational with full reuse; ~200t expendable claimed
A15: Vulcan Centaur | B15: USA | C15: ULA | D15: 2024 | E15: Active | F15: 27200 | G15: 9250 | H15: — | I15: 547000 | J15: 61.6 | K15: 5.4 | L15: Replaces Atlas V and Delta IV; 2 or 4 GEM-63XL strap-ons optional
A17: PER-STAGE MASS BREAKDOWN
A18: Vehicle | B18: Stage | C18: Engine | D18: # Engines | E18: Propellant Mass (kg) | F18: Dry Mass (kg) | G18: Gross Mass (kg) | H18: Struct. Frac. (%) | I18: Notes
A19: Falcon 9 Block 5 | B19: S1 Core | C19: Merlin 1D | D19: 9 | E19: 411000 | F19: 22200 | G19: 433200 | H19: 5.4 | I19: Reusable; includes grid fins, landing legs, interstage
B20: S2 Upper | C20: Merlin 1D Vac | D20: 1 | E20: 111500 | F20: 4000 | G20: 115500 | H20: 3.59 | I20: Single Merlin Vacuum engine
A21: Falcon Heavy | B21: Center Core | C21: Merlin 1D | D21: 9 | E21: 411000 | F21: 25600 | G21: 436600 | H21: 6.23 | I21: Reinforced; cross-feed ready
B22: Side Booster (x2) | C22: Merlin 1D | D22: 9 | E22: 411000 | F22: 22200 | G22: 433200 | H22: 5.4 | I22: Two identical; mass shown per booster
B23: S2 Upper | C23: Merlin 1D Vac | D23: 1 | E23: 111500 | F23: 4000 | G23: 115500 | H23: 3.59 | I23: Single Merlin Vacuum
A24: Atlas V 401 | B24: CBC Booster | C24: RD-180 | D24: 1 | E24: 284089 | F24: 21054 | G24: 305143 | H24: 7.41 | I24: Russian-built engine; kerosene/LOX
B25: Centaur III | C25: RL-10A-4-2 | D25: 1 | E25: 20830 | F25: 2316 | G25: 23146 | H25: 11.12 | I25: High-energy upper stage; LOX/LH2
A26: Delta IV Heavy | B26: Center CBC | C26: RS-68A | D26: 1 | E26: 202000 | F26: 26760 | G26: 228760 | H26: 13.25 | I26: LOX/LH2 core; mass per CBC
B27: Side CBC (x2) | C27: RS-68A | D27: 1 | E27: 202000 | F27: 26760 | G27: 228760 | H27: 13.25 | I27: Two identical side boosters; mass per booster
B28: DCSS | C28: RL-10B-2 | D28: 1 | E28: 27220 | F28: 3490 | G28: 30710 | H28: 12.82 | I28: Delta Cryogenic Second Stage; LOX/LH2
A29: Ariane 5 ECA | B29: EAP Solids (x2) | C29: P80 | D29: 1 | E29: 237000 | F29: 30000 | G29: 267000 | H29: 12.66 | I29: Solid strap-on; each booster; actual Isp ~274s; P80 shown as proxy
B30: EPC Core | C30: Vulcain 2 | D30: 1 | E30: 158000 | F30: 14700 | G30: 172700 | H30: 9.3 | I30: LOX/LH2 core stage
B31: ESC-A Upper | C31: HM7B | D31: 1 | E31: 14700 | F31: 1400 | G31: 16100 | H31: 9.52 | I31: LOX/LH2 upper stage; restartable
A32: Soyuz-2.1b | B32: Block B/V/G/D (x4) | C32: RD-107A | D32: 1 | E32: 39600 | F32: 3784 | G32: 43384 | H32: 9.56 | I32: 4 strap-on boosters; burn with core; mass per booster
B33: Block A Core | C33: RD-108A | D33: 1 | E33: 90360 | F33: 6545 | G33: 96905 | H33: 7.24 | I33: Burns simultaneously with boosters from liftoff
B34: Block I (S3) | C34: RD-0124 | D34: 4 | E34: 25400 | F34: 2355 | G34: 27755 | H34: 9.27 | I34: 4-chamber upper stage; high Isp
A35: Saturn V | B35: S-IC First | C35: F-1 | D35: 5 | E35: 2077000 | F35: 130000 | G35: 2207000 | H35: 6.26 | I35: LOX/RP-1; 5 F-1 engines
B36: S-II Second | C36: J-2 | D36: 5 | E36: 426000 | F36: 36200 | G36: 462200 | H36: 8.5 | I36: LOX/LH2; 5 J-2 engines
B37: S-IVB Third | C37: J-2 | D37: 1 | E37: 106000 | F37: 10000 | G37: 116000 | H37: 9.43 | I37: LOX/LH2; 1 J-2; also used as TMI stage
A38: SLS Block 1 | B38: SLS SRB (x2) | C38: SRB (SLS 5-seg) | D38: 1 | E38: 590000 | F38: 90718 | G38: 680718 | H38: 15.38 | I38: 5-segment solid strap-on; mass per booster
B39: Core Stage | C39: RS-25 (SSME) | D39: 4 | E39: 987000 | F39: 85000 | G39: 1072000 | H39: 8.61 | I39: LOX/LH2; 4 RS-25D engines
B40: ICPS Upper | C40: RL-10C-3 | D40: 1 | E40: 27220 | F40: 3500 | G40: 30720 | H40: 12.86 | I40: Interim Cryogenic Propulsion Stage; LOX/LH2
A41: New Glenn (7x2 Baseline) | B41: S1 First | C41: BE-4 | D41: 7 | E41: 770000 | F41: 55000 | G41: 825000 | H41: 7.14 | I41: LOX/CH4; 7 BE-4 baseline engines; reusable
...

Sheet Propellants
A1: PROPELLANT PROPERTIES
A2: Propellant | B2: Oxidizer | C2: Fuel | D2: Ox Density (kg/m³) | E2: Fuel Density (kg/m³) | F2: Mix Ratio (O/F) | G2: Bulk Density* (kg/m³) | H2: Typical Vac Isp (s) | I2: Storable? | J2: Notes
A3: LOX/RP-1 | B3: LOX | C3: RP-1 (Kerosene) | D3: 1141 | E3: 820 | F3: 2.56 | G3: 1051 | H3: 330 | I3: No | J3: Dense; good SL performance; not storable; workhorse combo
A4: LOX/LH2 | B4: LOX | C4: LH2 (Hydrogen) | D4: 1141 | E4: 71 | F4: 5.5 | G4: 976 | H4: 455 | I4: No | J4: Highest Isp; low density challenges; large tanks required
A5: LOX/CH4 | B5: LOX | C5: CH4 (Methane) | D5: 1141 | E5: 423 | F5: 3.55 | G5: 983 | H5: 360 | I5: No | J5: Good Isp + density; reusability-friendly; ISRU potential
A6: NTO/MMH | B6: NTO | C6: MMH | D6: 1450 | E6: 880 | F6: 1.65 | G6: 1235 | H6: 320 | I6: Yes | J6: Hypergolic; storable; common for upper stages and RCS
A7: NTO/UDMH | B7: NTO | C7: UDMH | D7: 1450 | E7: 793 | F7: 2.6 | G7: 1268 | H7: 310 | I7: Yes | J7: Hypergolic; storable; Russian/Chinese first stages
A8: NTO/Aerozine-50 | B8: NTO | C8: Aerozine-50 | D8: 1450 | E8: 900 | F8: 1.9 | G8: 1260 | H8: 320 | I8: Yes | J8: 50/50 N2H4+UDMH; Titan II/IV, Apollo CSM SPS
A9: Solid HTPB | B9: AP | C9: HTPB Binder | D9: 1790 | E9: 1050 | F9: 3.5 | G9: 1626 | H9: 285 | I9: Yes | J9: High density; simple ops; Isp 265-295s depending on formulation
A10: Solid PBAN | B10: AP | C10: PBAN Binder | D10: 1790 | E10: 1000 | F10: 3.5 | G10: 1614 | H10: 270 | I10: Yes | J10: Shuttle/SLS SRB propellant; similar to HTPB
A11: H2O2/RP-1 | B11: H2O2 | C11: RP-1 | D11: 1440 | E11: 820 | F11: 7 | G11: 1362 | H11: 300 | I11: No | J11: Green propellant; lower Isp than LOX/RP-1; non-cryogenic oxidizer
A12: LOX/Ethanol | B12: LOX | C12: Ethanol | D12: 1141 | E12: 789 | F12: 1.3 | G12: 988 | H12: 311 | I12: No | J12: Historical (V-2, Redstone); largely superseded by RP-1
A14: * Bulk density = mass-weighted average of oxidizer + fuel at stated mixture ratio
A16: SUBSYSTEM MASS FRACTION MODEL — Fractions as % of Propellant Mass
A17: Subsystem | B17: LOX/RP-1 (%) | C17: LOX/LH2 (%) | D17: LOX/CH4 (%) | E17: Solid (%) | F17: Hypergolic (%) | G17: Description
A18: Tank Structure | B18: 3.5 | C18: 6.5 | D18: 3.8 | E18: 1.8 | F18: 2.5 | G18: Propellant tanks, interstage, skirt structure; LH2 needs insulation
A19: Pressurization System | B19: 0.4 | C19: 0.6 | D19: 0.4 | E19: 0 | F19: 0.5 | G19: He pressurant tanks, regulators, lines; N/A for solids
A20: Feed System / Plumbing | B20: 0.8 | C20: 1 | D20: 0.8 | E20: 0.2 | F20: 0.6 | G20: Turbopumps, manifolds, valves, lines (exclusive of engine)
A21: Avionics / GNC | B21: 0.3 | C21: 0.4 | D21: 0.3 | E21: 0.2 | F21: 0.4 | G21: Flight computer, IMU, GPS, telemetry; typically fixed-ish mass
A22: Power System | B22: 0.2 | C22: 0.3 | D22: 0.2 | E22: 0.1 | F22: 0.2 | G22: Batteries, power distribution, wiring harness
A23: Thermal Control | B23: 0.2 | C23: 1 | D23: 0.3 | E23: 0.1 | F23: 0.3 | G23: MLI blankets, heaters, paint; LH2 stages significantly higher
A24: RCS / ACS | B24: 0.3 | C24: 0.4 | D24: 0.3 | E24: 0.1 | F24: 0.2 | G24: Reaction control thrusters, propellant, lines
A25: Separation System | B25: 0.1 | C25: 0.1 | D25: 0.1 | E25: 0.1 | F25: 0.1 | G25: Stage separation clampband / ordnance; fairing sep if applicable
A26: Recovery Hardware | B26: 0 | C26: 0 | D26: 0 | E26: 0 | F26: 0 | G26: Landing legs, grid fins, parachutes — add manually if reusable
A27: Residuals / Margin | B27: 0.5 | C27: 0.8 | D27: 0.5 | E27: 0.3 | F27: 0.5 | G27: Unusable propellant, trapped fluids, 3-5% mass growth margin
A28: TOTAL (excl. engines) | B28: 6.3 | C28: 11.1 | D28: 6.7 | E28: 2.9 | F28: 5.3

Sheet Comparison
A1: REFERENCE VEHICLE QUICK-COMPARE — Key Performance Metrics
A2: Vehicle | B2: Stages | C2: GLOW (kg) | D2: Payload LEO (kg) | E2: Payload Fraction (%) | F2: Payload GTO (kg) | G2: Propulsion | H2: Height (m) | I2: Status
A3: Falcon 9 Block 5 | B3: 2 | C3: 549054 | D3: 22800 | E3: 4.15 | F3: 8300 | G3: — | H3: 70 | I3: Active
A4: Falcon Heavy | B4: 3 | C4: 1420788 | D4: 63800 | E4: 4.49 | F4: 26700 | G4: — | H4: 70 | I4: Active
A5: Atlas V 401 | B5: 2 | C5: 334500 | D5: 9750 | E5: 2.91 | F5: 4750 | G5: — | H5: 58.3 | I5: Active (limited)
A6: Delta IV Heavy | B6: 3 | C6: 733400 | D6: 28370 | E6: 3.87 | F6: 14220 | G6: — | H6: 72 | I6: Retired 2024
A7: Ariane 5 ECA | B7: 3 | C7: 777000 | D7: 21000 | E7: 2.7 | F7: 10865 | G7: — | H7: 59 | I7: Retired 2023
A8: Soyuz-2.1b | B8: 3 | C8: 312000 | D8: 8200 | E8: 2.63 | F8: 2800 | G8: — | H8: 46.3 | I8: Active
A9: Saturn V | B9: 3 | C9: 2970000 | D9: 130000 | E9: 4.38 | F9: — | G9: — | H9: 110.6 | I9: Retired 1973
A10: SLS Block 1 | B10: 3 | C10: 2608000 | D10: 95000 | E10: 3.64 | F10: — | G10: — | H10: 98 | I10: Active
A11: New Glenn (7x2 Baseline) | B11: 2 | C11: 1000000 | D11: 45000 | E11: 4.5 | F11: 13000 | G11: — | H11: 98 | I11: Active
A12: New Glenn Block 2 (7x2 Upgraded) | B12: 2 | C12: 1000000 | D12: — | E12: — | F12: — | G12: — | H12: 98 | I12: Development
A13: New Glenn 9x4 | B13: 2 | C13: 1300000 | D13: 70000 | E13: 5.38 | F13: 14000 | G13: — | H13: 105 | I13: Development
A14: Starship (IFT-6 config) | B14: 2 | C14: 5000000 | D14: 150000 | E14: 3 | F14: — | G14: — | H14: 121 | I14: Development
A15: Vulcan Centaur | B15: 2 | C15: 547000 | D15: 27200 | E15: 4.97 | F15: 9250 | G15: — | H15: 61.6 | I15: Active
